<?xml version="1.0" ?>
<!-- =================================================================================== -->
<!-- |    This document was autogenerated by xacro from dual_arm_robot_car_grippers.urdf.xacro | -->
<!-- |    EDITING THIS FILE BY HAND IS NOT RECOMMENDED                                 | -->
<!-- =================================================================================== -->
<robot name="dual_arm_robot_car_grippers" xmlns:xacro="http://wiki.ros.org/xacro">
  <gazebo>
    <plugin filename="libgazebo_ros_control.so" name="ros_control">
      <!--robotNamespace>/</robotNamespace-->
      <!--robotSimType>gazebo_ros_control/DefaultRobotHWSim</robotSimType-->
      <legacyModeNS>true</legacyModeNS>
    </plugin>
    <!--
    <plugin name="gazebo_ros_power_monitor_controller" filename="libgazebo_ros_power_monitor.so">
      <alwaysOn>true</alwaysOn>
      <updateRate>1.0</updateRate>
      <timeout>5</timeout>
      <powerStateTopic>power_state</powerStateTopic>
      <powerStateRate>10.0</powerStateRate>
      <fullChargeCapacity>87.78</fullChargeCapacity>     
      <dischargeRate>-474</dischargeRate>
      <chargeRate>525</chargeRate>
      <dischargeVoltage>15.52</dischargeVoltage>
      <chargeVoltage>16.41</chargeVoltage>
    </plugin>
-->
  </gazebo>
  <!--
  Author: Felix Messmer
-->
  <!-- file has been edited because of same variable names in ur3 and ur10 -->
  <!--
  Author: Kelsey Hawkins
  Contributers: Jimmy Da Silva, Ajit Krisshna N L, Muhammad Asif Rana
-->
  <!-- This URDF was automatically created by SolidWorks to URDF Exporter! Originally created by Stephen Brawner (brawner@gmail.com) 
     Commit Version: 1.5.1-0-g916b5db  Build Version: 1.5.7152.31018
     For more information, please see http://wiki.ros.org/sw_urdf_exporter -->
  <link name="spoon_base_link">
    <inertial>
      <origin rpy="0 0 0" xyz="3.57488230036708E-05 0.0604869614071761 0.0555112383588204"/>
      <mass value="0.120623851760766"/>
      <inertia ixx="0.000272559245791058" ixy="-9.15002166382864E-08" ixz="-1.57907649856641E-07" iyy="0.000229228214845601" iyz="-9.78093298401894E-05" izz="0.000147326387999376"/>
    </inertial>
    <visual>
      <origin rpy="0 0 0" xyz="0 0 0"/>
      <geometry>
        <mesh filename="package://spoon_gripper/meshes/spoon_base_link.STL"/>
      </geometry>
      <material name="">
        <color rgba="1 1 1 1"/>
      </material>
    </visual>
    <collision>
      <origin rpy="0 0 0" xyz="0 0 0"/>
      <geometry>
        <mesh filename="package://spoon_gripper/meshes/spoon_base_link.STL"/>
      </geometry>
    </collision>
  </link>
  <link name="spoon_body">
    <inertial>
      <origin rpy="0 0 0" xyz="-5.3742E-06 0.20861 0.059391"/>
      <mass value="0.2975"/>
      <inertia ixx="0.0066466" ixy="1.1546E-07" ixz="3.2326E-08" iyy="0.0011732" iyz="-0.0023919" izz="0.0056526"/>
    </inertial>
    <visual>
      <origin rpy="0 0 0" xyz="0 0 0"/>
      <geometry>
        <mesh filename="package://spoon_gripper/meshes/spoon_body.STL"/>
      </geometry>
      <material name="">
        <color rgba="1 1 1 1"/>
      </material>
    </visual>
    <collision>
      <origin rpy="0 0 0" xyz="0 0 0"/>
      <geometry>
        <mesh filename="package://spoon_gripper/meshes/spoon_body.STL"/>
      </geometry>
    </collision>
  </link>
  <joint name="spoon_joint" type="fixed">
    <origin rpy="-2.0071 0 3.1416" xyz="0 -0.03747 0.40591"/>
    <parent link="spoon_base_link"/>
    <child link="spoon_body"/>
    <axis xyz="0 0 0"/>
  </joint>
  <!-- This URDF was automatically created by SolidWorks to URDF Exporter! Originally created by Stephen Brawner (brawner@gmail.com) 
     Commit Version: 1.5.1-0-g916b5db  Build Version: 1.5.7152.31018
     For more information, please see http://wiki.ros.org/sw_urdf_exporter -->
  <link name="ag95_grip_base_link">
    <inertial>
      <origin rpy="0 0 0" xyz="2.0713E-10 2.0278E-05 0.088235"/>
      <mass value="0.11208"/>
      <inertia ixx="2.9697E-05" ixy="-3.6572E-13" ixz="2.9903E-15" iyy="3.7674E-05" iyz="3.3862E-09" izz="4.0516E-05"/>
    </inertial>
    <visual>
      <origin rpy="0 0 0" xyz="0 0 0"/>
      <geometry>
        <mesh filename="package://ag95_grip_bowl/meshes/ag95_grip_base_link.STL"/>
      </geometry>
      <material name="">
        <color rgba="1 1 1 1"/>
      </material>
    </visual>
    <collision>
      <origin rpy="0 0 0" xyz="0 0 0"/>
      <geometry>
        <mesh filename="package://ag95_grip_bowl/meshes/ag95_grip_base_link.STL"/>
      </geometry>
    </collision>
  </link>
  <link name="grip_tip_link">
    <inertial>
      <origin rpy="0 0 0" xyz="0.0012187 -8.2438E-06 -0.032093"/>
      <mass value="0.024379"/>
      <inertia ixx="4.7514E-05" ixy="8.2047E-13" ixz="5.0873E-07" iyy="5.6442E-05" iyz="-5.2306E-14" izz="9.9339E-06"/>
    </inertial>
    <visual>
      <origin rpy="0 0 0" xyz="0 0 0"/>
      <geometry>
        <mesh filename="package://ag95_grip_bowl/meshes/grip_tip_link.STL"/>
      </geometry>
      <material name="">
        <color rgba="0.79216 0.81961 0.93333 1"/>
      </material>
    </visual>
    <collision>
      <origin rpy="0 0 0" xyz="0 0 0"/>
      <geometry>
        <mesh filename="package://ag95_grip_bowl/meshes/grip_tip_link.STL"/>
      </geometry>
    </collision>
  </link>
  <joint name="grip_tip_joint" type="fixed">
    <origin rpy="0 0.027068 0" xyz="-0.0011904 0 0.23817"/>
    <parent link="ag95_grip_base_link"/>
    <child link="grip_tip_link"/>
    <axis xyz="0.99963 0 0.027064"/>
    <limit effort="0" lower="0" upper="0" velocity="0"/>
  </joint>
  <!-- This URDF was automatically created by SolidWorks to URDF Exporter! Originally created by Stephen Brawner (brawner@gmail.com) 
     Commit Version: 1.5.1-0-g916b5db  Build Version: 1.5.7152.31018
     For more information, please see http://wiki.ros.org/sw_urdf_exporter -->
  <link name="body_link">
    <inertial>
      <origin rpy="0 0 0" xyz="4.02122942777527E-07 3.44169137633799E-15 0.00212528127877701"/>
      <mass value="2.19507335899911"/>
      <inertia ixx="0.0436806825633892" ixy="-5.08655266646313E-06" ixz="-3.34444135411209E-17" iyy="0.0455253476297357" iyz="-1.22445531747282E-16" izz="0.0891232981698546"/>
    </inertial>
    <visual>
      <origin rpy="0 0 0" xyz="0 0 0"/>
      <geometry>
        <mesh filename="package://car6/meshes/body_link.STL"/>
      </geometry>
      <material name="">
        <color rgba="1 1 1 1"/>
      </material>
    </visual>
    <collision>
      <origin rpy="0 0 0" xyz="0 0 0"/>
      <geometry>
        <mesh filename="package://car6/meshes/body_link.STL"/>
      </geometry>
    </collision>
  </link>
  <link name="link1">
    <inertial>
      <origin rpy="0 0 0" xyz="0 0.015 -2.77555756156289E-17"/>
      <mass value="0.196670527636265"/>
      <inertia ixx="0.00012319074315568" ixy="1.68055485182223E-21" ixz="5.68270902369089E-22" iyy="0.000221934036274288" iyz="-2.99013335426208E-20" izz="0.00012319074315568"/>
    </inertial>
    <visual>
      <origin rpy="0 0 0" xyz="0 0 0"/>
      <geometry>
        <mesh filename="package://car6/meshes/link1.STL"/>
      </geometry>
      <material name="">
        <color rgba="1 1 1 1"/>
      </material>
    </visual>
    <collision>
      <origin rpy="0 0 0" xyz="0 0 0"/>
      <geometry>
        <mesh filename="package://car6/meshes/link1.STL"/>
      </geometry>
    </collision>
  </link>
  <joint name="joint1" type="revolute">
    <origin rpy="0 0 3.1416" xyz="-0.37 -0.2765 0.022"/>
    ff
    
    <parent link="body_link"/>
    <child link="link1"/>
    <axis xyz="0 -1 0"/>
    <limit effort="100" lower="-3.14" upper="3.14" velocity="1"/>
  </joint>
  <link name="link2">
    <inertial>
      <origin rpy="0 0 0" xyz="1.11022302462516E-16 0.00555555555555555 8.32667268468867E-17"/>
      <mass value="0.196670527636265"/>
      <inertia ixx="0.00012319074315568" ixy="-1.88078947842729E-20" ixz="2.0545131216551E-22" iyy="0.000221934036274288" iyz="-1.86019000446159E-20" izz="0.00012319074315568"/>
    </inertial>
    <visual>
      <origin rpy="0 0 0" xyz="0 0 0"/>
      <geometry>
        <mesh filename="package://car6/meshes/link2.STL"/>
      </geometry>
      <material name="">
        <color rgba="1 1 1 1"/>
      </material>
    </visual>
    <collision>
      <origin rpy="0 0 0" xyz="0 0 0"/>
      <geometry>
        <mesh filename="package://car6/meshes/link2.STL"/>
      </geometry>
    </collision>
  </link>
  <joint name="joint2" type="revolute">
    <origin rpy="0 0 -3.1416" xyz="0.37 -0.28594 0.022"/>
    <parent link="body_link"/>
    <child link="link2"/>
    <axis xyz="0 -1 0"/>
    <limit effort="100" lower="-3.14" upper="3.14" velocity="1"/>
  </joint>
  <link name="link3">
    <inertial>
      <origin rpy="0 0 0" xyz="-1.11022302462516E-16 0.00555555555555559 5.55111512312578E-17"/>
      <mass value="0.196670527636265"/>
      <inertia ixx="0.00012319074315568" ixy="-8.41242213867249E-21" ixz="6.34199391620153E-22" iyy="0.000221934036274288" iyz="6.59046589990345E-20" izz="0.00012319074315568"/>
    </inertial>
    <visual>
      <origin rpy="0 0 0" xyz="0 0 0"/>
      <geometry>
        <mesh filename="package://car6/meshes/link3.STL"/>
      </geometry>
      <material name="">
        <color rgba="1 1 1 1"/>
      </material>
    </visual>
    <collision>
      <origin rpy="0 0 0" xyz="0 0 0"/>
      <geometry>
        <mesh filename="package://car6/meshes/link3.STL"/>
      </geometry>
    </collision>
  </link>
  <joint name="joint3" type="revolute">
    <origin rpy="0 0 0" xyz="0.37 0.28594 0.022"/>
    <parent link="body_link"/>
    <child link="link3"/>
    <axis xyz="0 -1 0"/>
    <limit effort="100" lower="-3.14" upper="3.14" velocity="1"/>
  </joint>
  <link name="link4">
    <inertial>
      <origin rpy="0 0 0" xyz="1.38777878078145E-17 -0.00555555555555542 -2.77555756156289E-17"/>
      <mass value="0.196670527636265"/>
      <inertia ixx="0.00012319074315568" ixy="-2.41157420217329E-21" ixz="3.0147920638297E-22" iyy="0.000221934036274288" iyz="7.15576279845473E-20" izz="0.00012319074315568"/>
    </inertial>
    <visual>
      <origin rpy="0 0 0" xyz="0 0 0"/>
      <geometry>
        <mesh filename="package://car6/meshes/link4.STL"/>
      </geometry>
      <material name="">
        <color rgba="1 1 1 1"/>
      </material>
    </visual>
    <collision>
      <origin rpy="0 0 0" xyz="0 0 0"/>
      <geometry>
        <mesh filename="package://car6/meshes/link4.STL"/>
      </geometry>
    </collision>
  </link>
  <joint name="joint4" type="revolute">
    <origin rpy="0 0 0" xyz="-0.37 0.29706 0.022"/>
    <parent link="body_link"/>
    <child link="link4"/>
    <axis xyz="0 -1 0"/>
    <limit effort="100" lower="-3.14" upper="3.14" velocity="1"/>
  </joint>
  <link name="fix_link">
    <inertial>
      <origin rpy="0 0 0" xyz="-0.00205175959116993 0.00354919045860191 0.230032668804987"/>
      <mass value="96.1246042097922"/>
      <inertia ixx="1.91388330168671" ixy="-2.38360107290611E-05" ixz="-2.0468759548067E-17" iyy="0.911239224486908" iyz="-5.55860947911324E-15" izz="1.93441225874395"/>
    </inertial>
    <visual>
      <origin rpy="0 0 0" xyz="0 0 0"/>
      <geometry>
        <mesh filename="package://car6/meshes/fix_link.STL"/>
      </geometry>
      <material name="">
        <color rgba="1 1 1 1"/>
      </material>
    </visual>
    <collision>
      <origin rpy="0 0 0" xyz="0 0 0"/>
      <geometry>
        <mesh filename="package://car6/meshes/fix_link.STL"/>
      </geometry>
    </collision>
  </link>
  <joint name="fix_joint" type="fixed">
    <origin rpy="0 0 0" xyz="0 0 0"/>
    <parent link="body_link"/>
    <child link="fix_link"/>
    <axis xyz="0 0 0"/>
  </joint>
  <gazebo>
    <plugin filename="libgazebo_ros_diff_drive.so" name="differential_drive_controller">
      <rosDebugLevel>Debug</rosDebugLevel>
      <publishWheelTF>true</publishWheelTF>
      <robotNamespace>/</robotNamespace>
      <publishTf>1</publishTf>
      <publishWheelJointState>true</publishWheelJointState>
      <alwaysOn>true</alwaysOn>
      <updateRate>100.0</updateRate>
      <legacyMode>true</legacyMode>
      <leftJoint>fix_joint</leftJoint>
      <wheelSeparation>2.19</wheelSeparation>
      <wheelDiameter>0.196</wheelDiameter>
      <broadcastTF>1</broadcastTF>
      <wheelTorque>30</wheelTorque>
      <wheelAcceleration>1.8</wheelAcceleration>
      <commandTopic>cmd_vel</commandTopic>
      <odometryFrame>odom</odometryFrame>
      <odometryTopic>odom</odometryTopic>
      <robotBaseFrame>body_link</robotBaseFrame>
    </plugin>
  </gazebo>
  <!-- place table -->
  <!-- <xacro:dizuo/> -->
  <!-- place world reference -->
  <!-- <link name="world"/>
  <joint name="world_joint" type="fixed">
    <parent link="world"/>
    <child link ="car_body_link"/>
    <origin xyz="-0.23 0.51 0.0" rpy="1.57 0.0 0.0" />
  </joint> -->
  <!-- measured from model -->
  <link name="ur3_base_link">
    <visual>
      <geometry>
        <mesh filename="package://ur_description/meshes/ur3/visual/base.dae"/>
      </geometry>
      <material name="LightGrey">
        <color rgba="0.7 0.7 0.7 1.0"/>
      </material>
    </visual>
    <collision>
      <geometry>
        <mesh filename="package://ur_description/meshes/ur3/collision/base.stl"/>
      </geometry>
    </collision>
    <inertial>
      <mass value="2.0"/>
      <origin rpy="0 0 0" xyz="0.0 0.0 0.0"/>
      <inertia ixx="0.0030531654454" ixy="0.0" ixz="0.0" iyy="0.0030531654454" iyz="0.0" izz="0.005625"/>
    </inertial>
  </link>
  <joint name="ur3_shoulder_pan_joint" type="revolute">
    <parent link="ur3_base_link"/>
    <child link="ur3_shoulder_link"/>
    <origin rpy="0.0 0.0 0.0" xyz="0.0 0.0 0.1519"/>
    <axis xyz="0 0 1"/>
    <limit effort="330.0" lower="-6.28318530718" upper="1.0471975512" velocity="2.16"/>
    <dynamics damping="0.0" friction="0.0"/>
  </joint>
  <link name="ur3_shoulder_link">
    <visual>
      <geometry>
        <mesh filename="package://ur_description/meshes/ur3/visual/shoulder.dae"/>
      </geometry>
      <material name="LightGrey">
        <color rgba="0.7 0.7 0.7 1.0"/>
      </material>
    </visual>
    <collision>
      <geometry>
        <mesh filename="package://ur_description/meshes/ur3/collision/shoulder.stl"/>
      </geometry>
    </collision>
    <inertial>
      <mass value="2.0"/>
      <origin rpy="0 0 0" xyz="0.0 0.0 0.0"/>
      <inertia ixx="0.0080931634294" ixy="0.0" ixz="0.0" iyy="0.0080931634294" iyz="0.0" izz="0.005625"/>
    </inertial>
  </link>
  <joint name="ur3_shoulder_lift_joint" type="revolute">
    <parent link="ur3_shoulder_link"/>
    <child link="ur3_upper_arm_link"/>
    <origin rpy="0.0 1.57079632679 0.0" xyz="0.0 0.1198 0.0"/>
    <axis xyz="0 1 0"/>
    <limit effort="330.0" lower="-2.79252680319" upper="-0.174532925199" velocity="2.16"/>
    <dynamics damping="0.0" friction="0.0"/>
  </joint>
  <link name="ur3_upper_arm_link">
    <visual>
      <geometry>
        <mesh filename="package://ur_description/meshes/ur3/visual/upperarm.dae"/>
      </geometry>
      <material name="LightGrey">
        <color rgba="0.7 0.7 0.7 1.0"/>
      </material>
    </visual>
    <collision>
      <geometry>
        <mesh filename="package://ur_description/meshes/ur3/collision/upperarm.stl"/>
      </geometry>
    </collision>
    <inertial>
      <mass value="3.42"/>
      <origin rpy="0 0 0" xyz="0.0 0.0 0.121825"/>
      <inertia ixx="0.0217284832211" ixy="0.0" ixz="0.0" iyy="0.0217284832211" iyz="0.0" izz="0.00961875"/>
    </inertial>
  </link>
  <joint name="ur3_elbow_joint" type="revolute">
    <parent link="ur3_upper_arm_link"/>
    <child link="ur3_forearm_link"/>
    <origin rpy="0.0 0.0 0.0" xyz="0.0 -0.0925 0.24365"/>
    <axis xyz="0 1 0"/>
    <limit effort="150.0" lower="-3.14159265359" upper="0.872664625997" velocity="3.15"/>
    <dynamics damping="0.0" friction="0.0"/>
  </joint>
  <link name="ur3_forearm_link">
    <visual>
      <geometry>
        <mesh filename="package://ur_description/meshes/ur3/visual/forearm.dae"/>
      </geometry>
      <material name="LightGrey">
        <color rgba="0.7 0.7 0.7 1.0"/>
      </material>
    </visual>
    <collision>
      <geometry>
        <mesh filename="package://ur_description/meshes/ur3/collision/forearm.stl"/>
      </geometry>
    </collision>
    <inertial>
      <mass value="1.26"/>
      <origin rpy="0 0 0" xyz="0.0 0.0 0.106625"/>
      <inertia ixx="0.00654680644378" ixy="0.0" ixz="0.0" iyy="0.00654680644378" iyz="0.0" izz="0.00354375"/>
    </inertial>
  </link>
  <joint name="ur3_wrist_1_joint" type="revolute">
    <parent link="ur3_forearm_link"/>
    <child link="ur3_wrist_1_link"/>
    <origin rpy="0.0 1.57079632679 0.0" xyz="0.0 0.0 0.21325"/>
    <axis xyz="0 1 0"/>
    <limit effort="54.0" lower="-6.28318530718" upper="6.28318530718" velocity="3.2"/>
    <dynamics damping="0.0" friction="0.0"/>
  </joint>
  <link name="ur3_wrist_1_link">
    <visual>
      <geometry>
        <mesh filename="package://ur_description/meshes/ur3/visual/wrist1.dae"/>
      </geometry>
      <material name="LightGrey">
        <color rgba="0.7 0.7 0.7 1.0"/>
      </material>
    </visual>
    <collision>
      <geometry>
        <mesh filename="package://ur_description/meshes/ur3/collision/wrist1.stl"/>
      </geometry>
    </collision>
    <inertial>
      <mass value="0.8"/>
      <origin rpy="0 0 0" xyz="0.0 0.08505 0.0"/>
      <inertia ixx="0.002084999166" ixy="0.0" ixz="0.0" iyy="0.002084999166" iyz="0.0" izz="0.00225"/>
    </inertial>
  </link>
  <joint name="ur3_wrist_2_joint" type="revolute">
    <parent link="ur3_wrist_1_link"/>
    <child link="ur3_wrist_2_link"/>
    <origin rpy="0.0 0.0 0.0" xyz="0.0 0.08505 0.0"/>
    <axis xyz="0 0 1"/>
    <limit effort="54.0" lower="-6.28318530718" upper="6.28318530718" velocity="3.2"/>
    <dynamics damping="0.0" friction="0.0"/>
  </joint>
  <link name="ur3_wrist_2_link">
    <visual>
      <geometry>
        <mesh filename="package://ur_description/meshes/ur3/visual/wrist2.dae"/>
      </geometry>
      <material name="LightGrey">
        <color rgba="0.7 0.7 0.7 1.0"/>
      </material>
    </visual>
    <collision>
      <geometry>
        <mesh filename="package://ur_description/meshes/ur3/collision/wrist2.stl"/>
      </geometry>
    </collision>
    <inertial>
      <mass value="0.8"/>
      <origin rpy="0 0 0" xyz="0.0 0.0 0.08535"/>
      <inertia ixx="0.002084999166" ixy="0.0" ixz="0.0" iyy="0.002084999166" iyz="0.0" izz="0.00225"/>
    </inertial>
  </link>
  <joint name="ur3_wrist_3_joint" type="revolute">
    <parent link="ur3_wrist_2_link"/>
    <child link="ur3_wrist_3_link"/>
    <origin rpy="0.0 0.0 0.0" xyz="0.0 0.0 0.08535"/>
    <axis xyz="0 1 0"/>
    <limit effort="54.0" lower="-9.42477796077" upper="9.42477796077" velocity="3.2"/>
    <dynamics damping="0.0" friction="0.0"/>
  </joint>
  <link name="ur3_wrist_3_link">
    <visual>
      <geometry>
        <mesh filename="package://ur_description/meshes/ur3/visual/wrist3.dae"/>
      </geometry>
      <material name="LightGrey">
        <color rgba="0.7 0.7 0.7 1.0"/>
      </material>
    </visual>
    <collision>
      <geometry>
        <mesh filename="package://ur_description/meshes/ur3/collision/wrist3.stl"/>
      </geometry>
    </collision>
    <inertial>
      <mass value="0.35"/>
      <origin rpy="1.57079632679 0 0" xyz="0.0 0.0619 0.0"/>
      <inertia ixx="0.00013626661216" ixy="0.0" ixz="0.0" iyy="0.00013626661216" iyz="0.0" izz="0.0001792"/>
    </inertial>
  </link>
  <joint name="ur3_ee_fixed_joint" type="fixed">
    <parent link="ur3_wrist_3_link"/>
    <child link="ur3_ee_link"/>
    <origin rpy="0.0 0.0 1.57079632679" xyz="0.0 0.0819 0.0"/>
  </joint>
  <link name="ur3_ee_link">
    <collision>
      <geometry>
        <box size="0.01 0.01 0.01"/>
      </geometry>
      <origin rpy="0 0 0" xyz="-0.01 0 0"/>
    </collision>
  </link>
  <transmission name="ur3_shoulder_pan_trans">
    <type>transmission_interface/SimpleTransmission</type>
    <joint name="ur3_shoulder_pan_joint">
      <hardwareInterface>hardware_interface/PositionJointInterface</hardwareInterface>
    </joint>
    <actuator name="ur3_shoulder_pan_motor">
      <mechanicalReduction>1</mechanicalReduction>
    </actuator>
  </transmission>
  <transmission name="ur3_shoulder_lift_trans">
    <type>transmission_interface/SimpleTransmission</type>
    <joint name="ur3_shoulder_lift_joint">
      <hardwareInterface>hardware_interface/PositionJointInterface</hardwareInterface>
    </joint>
    <actuator name="ur3_shoulder_lift_motor">
      <mechanicalReduction>1</mechanicalReduction>
    </actuator>
  </transmission>
  <transmission name="ur3_elbow_trans">
    <type>transmission_interface/SimpleTransmission</type>
    <joint name="ur3_elbow_joint">
      <hardwareInterface>hardware_interface/PositionJointInterface</hardwareInterface>
    </joint>
    <actuator name="ur3_elbow_motor">
      <mechanicalReduction>1</mechanicalReduction>
    </actuator>
  </transmission>
  <transmission name="ur3_wrist_1_trans">
    <type>transmission_interface/SimpleTransmission</type>
    <joint name="ur3_wrist_1_joint">
      <hardwareInterface>hardware_interface/PositionJointInterface</hardwareInterface>
    </joint>
    <actuator name="ur3_wrist_1_motor">
      <mechanicalReduction>1</mechanicalReduction>
    </actuator>
  </transmission>
  <transmission name="ur3_wrist_2_trans">
    <type>transmission_interface/SimpleTransmission</type>
    <joint name="ur3_wrist_2_joint">
      <hardwareInterface>hardware_interface/PositionJointInterface</hardwareInterface>
    </joint>
    <actuator name="ur3_wrist_2_motor">
      <mechanicalReduction>1</mechanicalReduction>
    </actuator>
  </transmission>
  <transmission name="ur3_wrist_3_trans">
    <type>transmission_interface/SimpleTransmission</type>
    <joint name="ur3_wrist_3_joint">
      <hardwareInterface>hardware_interface/PositionJointInterface</hardwareInterface>
    </joint>
    <actuator name="ur3_wrist_3_motor">
      <mechanicalReduction>1</mechanicalReduction>
    </actuator>
  </transmission>
  <gazebo reference="ur3_shoulder_link">
    <selfCollide>true</selfCollide>
  </gazebo>
  <gazebo reference="ur3_upper_arm_link">
    <selfCollide>true</selfCollide>
  </gazebo>
  <gazebo reference="ur3_forearm_link">
    <selfCollide>true</selfCollide>
  </gazebo>
  <gazebo reference="ur3_wrist_1_link">
    <selfCollide>true</selfCollide>
  </gazebo>
  <gazebo reference="ur3_wrist_3_link">
    <selfCollide>true</selfCollide>
  </gazebo>
  <gazebo reference="ur3_wrist_2_link">
    <selfCollide>true</selfCollide>
  </gazebo>
  <gazebo reference="ur3_ee_link">
    <selfCollide>true</selfCollide>
  </gazebo>
  <!-- ROS base_link to UR 'Base' Coordinates transform -->
  <link name="ur3_base"/>
  <joint name="ur3_base_link-base_fixed_joint" type="fixed">
    <!-- NOTE: this rotation is only needed as long as base_link itself is
                 not corrected wrt the real robot (ie: rotated over 180
                 degrees)
      -->
    <origin rpy="0 0 -3.14159265359" xyz="0 0 0"/>
    <parent link="ur3_base_link"/>
    <child link="ur3_base"/>
  </joint>
  <!-- Frame coincident with all-zeros TCP on UR controller -->
  <link name="ur3_tool0"/>
  <joint name="ur3_wrist_3_link-tool0_fixed_joint" type="fixed">
    <origin rpy="-1.57079632679 0 0" xyz="0 0.0819 0"/>
    <parent link="ur3_wrist_3_link"/>
    <child link="ur3_tool0"/>
  </joint>
  <joint name="ur3_platform_mount" type="fixed">
    <parent link="body_link"/>
    <child link="ur3_base_link"/>
    <origin rpy="0 0 1.57079632679" xyz="-0.37 0 0.40"/>
  </joint>
  <joint name="ag95" type="fixed">
    <parent link="ur3_ee_link"/>
    <child link="ag95_grip_base_link"/>
    <origin rpy="0 1.57079632679 0" xyz="0 0 0"/>
  </joint>
  <!-- measured from model -->
  <link name="ur10_base_link">
    <visual>
      <geometry>
        <mesh filename="package://ur_description/meshes/ur10/visual/base.dae"/>
      </geometry>
      <material name="LightGrey">
        <color rgba="0.7 0.7 0.7 1.0"/>
      </material>
    </visual>
    <collision>
      <geometry>
        <mesh filename="package://ur_description/meshes/ur10/collision/base.stl"/>
      </geometry>
    </collision>
    <inertial>
      <mass value="4.0"/>
      <origin rpy="0 0 0" xyz="0.0 0.0 0.0"/>
      <inertia ixx="0.0061063308908" ixy="0.0" ixz="0.0" iyy="0.0061063308908" iyz="0.0" izz="0.01125"/>
    </inertial>
  </link>
  <joint name="ur10_shoulder_pan_joint" type="revolute">
    <parent link="ur10_base_link"/>
    <child link="ur10_shoulder_link"/>
    <origin rpy="0.0 0.0 0.0" xyz="0.0 0.0 0.1273"/>
    <axis xyz="0 0 1"/>
    <limit effort="330.0" lower="-1.2217304764" upper="0.523598775598" velocity="2.16"/>
    <dynamics damping="0.0" friction="0.0"/>
  </joint>
  <link name="ur10_shoulder_link">
    <visual>
      <geometry>
        <mesh filename="package://ur_description/meshes/ur10/visual/shoulder.dae"/>
      </geometry>
      <material name="LightGrey">
        <color rgba="0.7 0.7 0.7 1.0"/>
      </material>
    </visual>
    <collision>
      <geometry>
        <mesh filename="package://ur_description/meshes/ur10/collision/shoulder.stl"/>
      </geometry>
    </collision>
    <inertial>
      <mass value="7.778"/>
      <origin rpy="0 0 0" xyz="0.0 0.0 0.0"/>
      <inertia ixx="0.0314743125769" ixy="0.0" ixz="0.0" iyy="0.0314743125769" iyz="0.0" izz="0.021875625"/>
    </inertial>
  </link>
  <joint name="ur10_shoulder_lift_joint" type="revolute">
    <parent link="ur10_shoulder_link"/>
    <child link="ur10_upper_arm_link"/>
    <origin rpy="0.0 1.57079632679 0.0" xyz="0.0 0.220941 0.0"/>
    <axis xyz="0 1 0"/>
    <limit effort="330.0" lower="-2.61799387799" upper="-0.174532925199" velocity="2.16"/>
    <dynamics damping="0.0" friction="0.0"/>
  </joint>
  <link name="ur10_upper_arm_link">
    <visual>
      <geometry>
        <mesh filename="package://ur_description/meshes/ur10/visual/upperarm.dae"/>
      </geometry>
      <material name="LightGrey">
        <color rgba="0.7 0.7 0.7 1.0"/>
      </material>
    </visual>
    <collision>
      <geometry>
        <mesh filename="package://ur_description/meshes/ur10/collision/upperarm.stl"/>
      </geometry>
    </collision>
    <inertial>
      <mass value="12.93"/>
      <origin rpy="0 0 0" xyz="0.0 -0.045 0.306"/>
      <inertia ixx="0.421753803798" ixy="0.0" ixz="0.0" iyy="0.421753803798" iyz="0.0" izz="0.036365625"/>
    </inertial>
  </link>
  <joint name="ur10_elbow_joint" type="revolute">
    <parent link="ur10_upper_arm_link"/>
    <child link="ur10_forearm_link"/>
    <origin rpy="0.0 0.0 0.0" xyz="0.0 -0.1719 0.612"/>
    <axis xyz="0 1 0"/>
    <limit effort="150.0" lower="0.0" upper="2.79252680319" velocity="3.15"/>
    <dynamics damping="0.0" friction="0.0"/>
  </joint>
  <link name="ur10_forearm_link">
    <visual>
      <geometry>
        <mesh filename="package://ur_description/meshes/ur10/visual/forearm.dae"/>
      </geometry>
      <material name="LightGrey">
        <color rgba="0.7 0.7 0.7 1.0"/>
      </material>
    </visual>
    <collision>
      <geometry>
        <mesh filename="package://ur_description/meshes/ur10/collision/forearm.stl"/>
      </geometry>
    </collision>
    <inertial>
      <mass value="3.87"/>
      <origin rpy="0 0 0" xyz="0.0 0.0 0.28615"/>
      <inertia ixx="0.111069694097" ixy="0.0" ixz="0.0" iyy="0.111069694097" iyz="0.0" izz="0.010884375"/>
    </inertial>
  </link>
  <joint name="ur10_wrist_1_joint" type="revolute">
    <parent link="ur10_forearm_link"/>
    <child link="ur10_wrist_1_link"/>
    <origin rpy="0.0 1.57079632679 0.0" xyz="0.0 0.0 0.5723"/>
    <axis xyz="0 1 0"/>
    <limit effort="54.0" lower="-6.28318530718" upper="6.28318530718" velocity="3.2"/>
    <dynamics damping="0.0" friction="0.0"/>
  </joint>
  <link name="ur10_wrist_1_link">
    <visual>
      <geometry>
        <mesh filename="package://ur_description/meshes/ur10/visual/wrist1.dae"/>
      </geometry>
      <material name="LightGrey">
        <color rgba="0.7 0.7 0.7 1.0"/>
      </material>
    </visual>
    <collision>
      <geometry>
        <mesh filename="package://ur_description/meshes/ur10/collision/wrist1.stl"/>
      </geometry>
    </collision>
    <inertial>
      <mass value="1.96"/>
      <origin rpy="0 0 0" xyz="0.0 0.1149 0.0"/>
      <inertia ixx="0.0051082479567" ixy="0.0" ixz="0.0" iyy="0.0051082479567" iyz="0.0" izz="0.0055125"/>
    </inertial>
  </link>
  <joint name="ur10_wrist_2_joint" type="revolute">
    <parent link="ur10_wrist_1_link"/>
    <child link="ur10_wrist_2_link"/>
    <origin rpy="0.0 0.0 0.0" xyz="0.0 0.1149 0.0"/>
    <axis xyz="0 0 1"/>
    <limit effort="54.0" lower="-3.14159265359" upper="-0.698131700798" velocity="3.2"/>
    <dynamics damping="0.0" friction="0.0"/>
  </joint>
  <link name="ur10_wrist_2_link">
    <visual>
      <geometry>
        <mesh filename="package://ur_description/meshes/ur10/visual/wrist2.dae"/>
      </geometry>
      <material name="LightGrey">
        <color rgba="0.7 0.7 0.7 1.0"/>
      </material>
    </visual>
    <collision>
      <geometry>
        <mesh filename="package://ur_description/meshes/ur10/collision/wrist2.stl"/>
      </geometry>
    </collision>
    <inertial>
      <mass value="1.96"/>
      <origin rpy="0 0 0" xyz="0.0 0.0 0.1157"/>
      <inertia ixx="0.0051082479567" ixy="0.0" ixz="0.0" iyy="0.0051082479567" iyz="0.0" izz="0.0055125"/>
    </inertial>
  </link>
  <joint name="ur10_wrist_3_joint" type="revolute">
    <parent link="ur10_wrist_2_link"/>
    <child link="ur10_wrist_3_link"/>
    <origin rpy="0.0 0.0 0.0" xyz="0.0 0.0 0.1157"/>
    <axis xyz="0 1 0"/>
    <limit effort="54.0" lower="-6.28318530718" upper="6.28318530718" velocity="3.2"/>
    <dynamics damping="0.0" friction="0.0"/>
  </joint>
  <link name="ur10_wrist_3_link">
    <visual>
      <geometry>
        <mesh filename="package://ur_description/meshes/ur10/visual/wrist3.dae"/>
      </geometry>
      <material name="LightGrey">
        <color rgba="0.7 0.7 0.7 1.0"/>
      </material>
    </visual>
    <collision>
      <geometry>
        <mesh filename="package://ur_description/meshes/ur10/collision/wrist3.stl"/>
      </geometry>
    </collision>
    <inertial>
      <mass value="0.202"/>
      <origin rpy="1.57079632679 0 0" xyz="0.0 0.07695 0.0"/>
      <inertia ixx="0.000117921661165" ixy="0.0" ixz="0.0" iyy="0.000117921661165" iyz="0.0" izz="0.000204525"/>
    </inertial>
  </link>
  <joint name="ur10_ee_fixed_joint" type="fixed">
    <parent link="ur10_wrist_3_link"/>
    <child link="ur10_ee_link"/>
    <origin rpy="0.0 0.0 1.57079632679" xyz="0.0 0.0922 0.0"/>
  </joint>
  <link name="ur10_ee_link">
    <collision>
      <geometry>
        <box size="0.01 0.01 0.01"/>
      </geometry>
      <origin rpy="0 0 0" xyz="-0.01 0 0"/>
    </collision>
  </link>
  <transmission name="ur10_shoulder_pan_trans">
    <type>transmission_interface/SimpleTransmission</type>
    <joint name="ur10_shoulder_pan_joint">
      <hardwareInterface>hardware_interface/PositionJointInterface</hardwareInterface>
    </joint>
    <actuator name="ur10_shoulder_pan_motor">
      <mechanicalReduction>1</mechanicalReduction>
    </actuator>
  </transmission>
  <transmission name="ur10_shoulder_lift_trans">
    <type>transmission_interface/SimpleTransmission</type>
    <joint name="ur10_shoulder_lift_joint">
      <hardwareInterface>hardware_interface/PositionJointInterface</hardwareInterface>
    </joint>
    <actuator name="ur10_shoulder_lift_motor">
      <mechanicalReduction>1</mechanicalReduction>
    </actuator>
  </transmission>
  <transmission name="ur10_elbow_trans">
    <type>transmission_interface/SimpleTransmission</type>
    <joint name="ur10_elbow_joint">
      <hardwareInterface>hardware_interface/PositionJointInterface</hardwareInterface>
    </joint>
    <actuator name="ur10_elbow_motor">
      <mechanicalReduction>1</mechanicalReduction>
    </actuator>
  </transmission>
  <transmission name="ur10_wrist_1_trans">
    <type>transmission_interface/SimpleTransmission</type>
    <joint name="ur10_wrist_1_joint">
      <hardwareInterface>hardware_interface/PositionJointInterface</hardwareInterface>
    </joint>
    <actuator name="ur10_wrist_1_motor">
      <mechanicalReduction>1</mechanicalReduction>
    </actuator>
  </transmission>
  <transmission name="ur10_wrist_2_trans">
    <type>transmission_interface/SimpleTransmission</type>
    <joint name="ur10_wrist_2_joint">
      <hardwareInterface>hardware_interface/PositionJointInterface</hardwareInterface>
    </joint>
    <actuator name="ur10_wrist_2_motor">
      <mechanicalReduction>1</mechanicalReduction>
    </actuator>
  </transmission>
  <transmission name="ur10_wrist_3_trans">
    <type>transmission_interface/SimpleTransmission</type>
    <joint name="ur10_wrist_3_joint">
      <hardwareInterface>hardware_interface/PositionJointInterface</hardwareInterface>
    </joint>
    <actuator name="ur10_wrist_3_motor">
      <mechanicalReduction>1</mechanicalReduction>
    </actuator>
  </transmission>
  <gazebo reference="ur10_shoulder_link">
    <selfCollide>true</selfCollide>
  </gazebo>
  <gazebo reference="ur10_upper_arm_link">
    <selfCollide>true</selfCollide>
  </gazebo>
  <gazebo reference="ur10_forearm_link">
    <selfCollide>true</selfCollide>
  </gazebo>
  <gazebo reference="ur10_wrist_1_link">
    <selfCollide>true</selfCollide>
  </gazebo>
  <gazebo reference="ur10_wrist_3_link">
    <selfCollide>true</selfCollide>
  </gazebo>
  <gazebo reference="ur10_wrist_2_link">
    <selfCollide>true</selfCollide>
  </gazebo>
  <gazebo reference="ur10_ee_link">
    <selfCollide>true</selfCollide>
  </gazebo>
  <!-- ROS base_link to UR 'Base' Coordinates transform -->
  <link name="ur10_base"/>
  <joint name="ur10_base_link-base_fixed_joint" type="fixed">
    <!-- NOTE: this rotation is only needed as long as base_link itself is
                 not corrected wrt the real robot (ie: rotated over 180
                 degrees)
      -->
    <origin rpy="0 0 -3.14159265359" xyz="0 0 0"/>
    <parent link="ur10_base_link"/>
    <child link="ur10_base"/>
  </joint>
  <!-- Frame coincident with all-zeros TCP on UR controller -->
  <link name="ur10_tool0"/>
  <joint name="ur10_wrist_3_link-tool0_fixed_joint" type="fixed">
    <origin rpy="-1.57079632679 0 0" xyz="0 0.0922 0"/>
    <parent link="ur10_wrist_3_link"/>
    <child link="ur10_tool0"/>
  </joint>
  <joint name="ur10_platform_mount" type="fixed">
    <parent link="body_link"/>
    <child link="ur10_base_link"/>
    <origin rpy="0 0 -1.57079632679" xyz="0.37 0.0 0.40"/>
  </joint>
  <joint name="spoon" type="fixed">
    <parent link="ur10_ee_link"/>
    <child link="spoon_base_link"/>
    <origin rpy="-1.57079632679 -0.785398163397 -1.57079632679" xyz="0 0 0"/>
  </joint>
  <!-- place ur10 endeffector -->
  <!-- <xacro:endeffector prefix="$(arg prefix_ur10)"/>
  <joint name="$(arg prefix_ur10)ee_mount" type="fixed">
    <parent link="$(arg prefix_ur10)ee_link" />
    <child link = "$(arg prefix_ur10)ee_frame" />
    <origin xyz="0.0 0.0 0.0" rpy="${pi/2.0} 0.0 ${pi/2.0}" />
  </joint> -->
  <!--
  <joint name="$(arg prefix_ur10)ee_mount" type="fixed">
    <parent link="$(arg prefix_ur10)tool0"/>
    <child link ="$(arg prefix_ur10)ee_frame"/>
    <origin xyz="0 0 0" rpy="0 0 ${pi}" />
  </joint>
-->
</robot>
